<mujoco model="wl">
  <option iterations="50" timestep="0.001" solver="PGS" gravity="0 0 -9.81" />

  <compiler angle="radian" meshdir="meshes" eulerseq="zyx" autolimits="true" />

  <default>
    <joint limited="true" damping="0.01" armature="0.01" frictionloss="0.01" />
    <geom condim="4" contype="2" conaffinity="2" friction="0.9 0.2 0.2" solref="0.001 2" />
    <motor ctrllimited="true" />
    <equality solref="0.001 2" />
    <default class="visualgeom">
      <geom material="visualgeom" condim="1" contype="0" conaffinity="0" />
    </default>
  </default>

  <asset>
    <mesh name="base_link" file="base_link.STL" />
    <mesh name="lf0_Link" file="lf0_Link.STL" />
    <mesh name="lf1_Link" file="lf1_Link.STL" />
    <mesh name="rf0_Link" file="rf0_Link.STL" />
    <mesh name="rf1_Link" file="rf1_Link.STL" />
    <texture name="texplane" type="2d" builtin="checker" rgb1=".0 .0 .0" rgb2=".8 .8 .8" width="100" height="100" />
    <material name="matplane" reflectance="0." texture="texplane" texrepeat="1 1" texuniform="true" />
    <material name="visualgeom" rgba="0.5 0.9 0.2 1" />
  </asset>

  <worldbody>
    <light directional="true" diffuse="0.4 0.4 0.4" specular="0.1 0.1 0.1" pos="0 0 5.0" dir="0 0 -1" castshadow="false" />
    <light directional="true" diffuse="0.6 0.6 0.6" specular="0.2 0.2 0.2" pos="0 0 4" dir="0 0 -1" />
    <geom name="ground" type="plane" pos="0 0 0" size="100 100 0.001" quat="1 0 0 0" material="matplane" condim="3" contype="1" conaffinity="15" />
    <!-- <camera name="side_view" mode="trackcom" pos="5.0 0 2.0" xyaxes="0 1 0 0 0 1" /> -->
    <!-- <camera name="fixed" pos="0 -10.0 2.0" xyaxes="1 0 0 0 0 1" /> -->
    <camera name="track" mode="trackcom" pos="0 -5.0 0.69" xyaxes="1 0 0 0 0 1" />
    <body name="root" pos="0 0 0.5" quat="1 0 0 0">
      <!-- <freejoint name="root" /> -->
      <site name="torso" size="0.01" pos="0 0 0" />
      <geom name="base_collision" type="mesh" rgba="0.79216 0.81961 0.93333 1" mesh="base_link" contype="0" conaffinity="0" density="0" group="1" class="visualgeom" />
      <geom type="mesh" rgba="0.79216 0.81961 0.93333 1" mesh="base_link" contype="1" conaffinity="0" />
      <body name="lf0_Link" pos="0.054 0.1705 0.131" quat="0.707105 -0.707108 0 0">
        <inertial pos="0.0597664 -0.00048182 0.0119824" quat="-0.0135897 0.745051 -0.0154639 0.66669" mass="0.16" diaginertia="0.00118422 0.00116062 5.03506e-05" />
        <joint name="lf0_Joint" pos="0 0 0" axis="0 0 1" range="-0.3363 1.3479" actuatorfrcrange="-30 30" />
        <geom name="lf0_collision" type="mesh" rgba="0.792157 0.819608 0.933333 1" mesh="lf0_Link" contype="0" conaffinity="0" density="0" group="1" class="visualgeom" />
        <geom type="mesh" rgba="0.792157 0.819608 0.933333 1" mesh="lf0_Link" contype="1" conaffinity="0" />
        <body name="lf1_Link" pos="0.15 -0.00010199 0.0205">
          <inertial pos="-0.00032544 0.158998 0.00798168" quat="0.500939 0.48396 -0.498705 0.515884" mass="0.36" diaginertia="0.0125278 0.0124877 0.000104199" />
          <joint name="lf1_Joint" pos="0 0 0" axis="0 0 1" range="-1 1.25" actuatorfrcrange="-30 30" />
          <geom name="lf1_collision" type="mesh" rgba="0.792157 0.819608 0.933333 1" mesh="lf1_Link" contype="0" conaffinity="0" density="0" group="1" class="visualgeom" />
          <geom type="mesh" rgba="0.792157 0.819608 0.933333 1" mesh="lf1_Link" contype="1" conaffinity="0" />
          <body name="l_wheel_Link" pos="1.857e-05 0.25 0.0275">
            <inertial pos="-4.507e-05 -0.00038447 0.0237603" quat="0.666367 0.00284682 0.0874849 0.740469" mass="1.22" diaginertia="0.00176063 0.00174355 0.00173939" />
            <joint name="l_wheel_Joint" pos="0 0 0" axis="0 0 1" limited="false"/>
            <geom name="l_wheel_collision" size="0.0675 0.0125" pos="0 0 0.03" type="cylinder" rgba="0.792157 0.819608 0.933333 1" contype="0" conaffinity="0" density="0" group="1" class="visualgeom" />
            <geom type="cylinder" size="0.0675 0.0125" rgba="0.792157 0.819608 0.933333 1" pos="0 0 0.03" contype="1" conaffinity="0" />
          </body>
        </body>
      </body>
      <body name="rf0_Link" pos="0.054 -0.1705 0.131" quat="0.707105 0.707108 0 0">
        <inertial pos="0.0597664 -0.00048182 0.0119824" quat="-0.00848515 0.745134 -0.0107131 0.666775" mass="0.16" diaginertia="0.0011842 0.00116065 5.03478e-05" />
        <joint name="rf0_Joint" pos="0 0 0" axis="0 0 1" range="-1.3479 0.3363" actuatorfrcrange="-30 30" />
        <geom name="rf0_collision" type="mesh" rgba="0.792157 0.819608 0.933333 1" mesh="rf0_Link" contype="0" conaffinity="0" density="0" group="1" class="visualgeom" />
        <geom type="mesh" rgba="0.792157 0.819608 0.933333 1" mesh="rf0_Link" contype="1" conaffinity="0" />
        <body name="rf1_Link" pos="0.15 9.5536e-05 0.0205">
          <inertial pos="0.00032544 -0.158998 0.00798168" quat="0.499449 0.516586 -0.500215 0.483192" mass="0.36" diaginertia="0.0125278 0.0124877 0.000104197" />
          <joint name="rf1_Joint" pos="0 0 0" axis="0 0 1" range="-1.25 1" actuatorfrcrange="-30 30" />
          <geom name="rf1_collision" type="mesh" rgba="0.792157 0.819608 0.933333 1" mesh="rf1_Link" contype="0" conaffinity="0" density="0" group="1" class="visualgeom" />
          <geom type="mesh" rgba="0.792157 0.819608 0.933333 1" mesh="rf1_Link" contype="1" conaffinity="0" />
          <body name="r_wheel_Link" pos="1.5909e-05 -0.25 0.0275">
            <inertial pos="0.00038403 4.865e-05 0.0237603" quat="0.994132 0.0696225 -0.0602894 -0.0567401" mass="1.22" diaginertia="0.00176062 0.00174356 0.00173938" />
            <joint name="r_wheel_Joint" pos="0 0 0" axis="0 0 1" limited="false"/>
            <geom name="r_wheel_collision" size="0.0675 0.0125" pos="0 0 0.03" type="cylinder" rgba="0.792157 0.819608 0.933333 1" contype="0" conaffinity="0" density="0" group="1" class="visualgeom" />
            <geom type="cylinder" size="0.0675 0.0125" rgba="0.792157 0.819608 0.933333 1" pos="0 0 0.03" contype="1" conaffinity="0" />
          </body>
        </body>
      </body>
    </body>
  </worldbody>

  <actuator>
    <motor joint="lf0_Joint" name="lf0_Joint" gear="1" ctrllimited="true" ctrlrange="-30 30"/>
    <motor joint="lf1_Joint" name="lf1_Joint" gear="1" ctrllimited="true" ctrlrange="-30 30"/>
    <motor joint="l_wheel_Joint" name="l_wheel_Joint" gear="1" ctrllimited="true" ctrlrange="-30 30"/>
    <motor joint="rf0_Joint" name="rf0_Joint" gear="1" ctrllimited="true" ctrlrange="-30 30"/>
    <motor joint="rf1_Joint" name="rf1_Joint" gear="1" ctrllimited="true" ctrlrange="-30 30"/>
    <motor joint="r_wheel_Joint" name="r_wheel_Joint" gear="1" ctrllimited="true" ctrlrange="-30 30"/>
  </actuator>

  <sensor>
    <framepos name="torso_pos" objtype="site" objname="torso" noise="0" />
    <framequat name="torso_quat" objtype="site" objname="torso" noise="0.003" />
      <framelinvel name="torso_linvel" objtype="site" objname="torso" noise="0" />
      <frameangvel name="torso_angvel" objtype="site" objname="torso" noise="0.005" />
      <framelinacc name="torso_linacc" objtype="site" objname="torso" noise="0.005" />
    <jointpos name="lf0_Joint_p" joint="lf0_Joint" noise="0.001"/>
    <jointvel name="lf0_Joint_v" joint="lf0_Joint" noise="0.001"/>
    <jointpos name="lf1_Joint_p" joint="lf1_Joint" noise="0.001"/>
    <jointvel name="lf1_Joint_v" joint="lf1_Joint" noise="0.001"/>
    <jointpos name="l_wheel_Joint_p" joint="l_wheel_Joint" noise="0.001"/>
    <jointvel name="l_wheel_Joint_v" joint="l_wheel_Joint" noise="0.001"/>
    <jointpos name="rf0_Joint_p" joint="rf0_Joint" noise="0.001"/>
    <jointvel name="rf0_Joint_v" joint="rf0_Joint" noise="0.001"/>
    <jointpos name="rf1_Joint_p" joint="rf1_Joint" noise="0.001"/>
    <jointvel name="rf1_Joint_v" joint="rf1_Joint" noise="0.001"/>
    <jointpos name="r_wheel_Joint_p" joint="r_wheel_Joint" noise="0.001"/>
    <jointvel name="r_wheel_Joint_v" joint="r_wheel_Joint" noise="0.001"/>
  </sensor>
</mujoco>
